<?xml version="1.0" encoding="UTF-8"?>
<!-- Generated by org.testng.reporters.JUnitReportReporter -->
<testsuite hostname="VNNOT01519" failures="8" tests="14" name="testcases.LoginTest" time="52.016" errors="0" timestamp="2025-07-02T13:26:29 ICT" skipped="0">
  <testcase classname="testcases.LoginTest" name="loginSuccess" time="5.503">
    <failure message="FAIL Because Still in the Login page: expected [false] but found [true]" type="java.lang.AssertionError">
      <![CDATA[java.lang.AssertionError: FAIL Because Still in the Login page: expected [false] but found [true]
at org.testng.Assert.fail(Assert.java:111)
at org.testng.Assert.failNotEquals(Assert.java:1590)
at org.testng.Assert.assertFalse(Assert.java:79)
at keywords.WebUI.assertNotContains(WebUI.java:468)
at pages.LoginPage.verifyLoginSuccess(LoginPage.java:41)
at testcases.LoginTest.loginSuccess(LoginTest.java:41)
at java.base/jdk.internal.reflect.DirectMethodHandleAccessor.invoke(DirectMethodHandleAccessor.java:103)
at java.base/java.lang.reflect.Method.invoke(Method.java:580)
at org.testng.internal.invokers.MethodInvocationHelper.invokeMethod(MethodInvocationHelper.java:141)
at org.testng.internal.invokers.TestInvoker.invokeMethod(TestInvoker.java:687)
at org.testng.internal.invokers.TestInvoker.invokeTestMethod(TestInvoker.java:230)
at org.testng.internal.invokers.MethodRunner.runInSequence(MethodRunner.java:63)
at org.testng.internal.invokers.TestInvoker$MethodInvocationAgent.invoke(TestInvoker.java:995)
at org.testng.internal.invokers.TestInvoker.invokeTestMethods(TestInvoker.java:203)
at org.testng.internal.invokers.TestMethodWorker.invokeTestMethods(TestMethodWorker.java:154)
at org.testng.internal.invokers.TestMethodWorker.run(TestMethodWorker.java:134)
at java.base/java.util.ArrayList.forEach(ArrayList.java:1596)
at org.testng.TestRunner.privateRun(TestRunner.java:741)
at org.testng.TestRunner.run(TestRunner.java:616)
at org.testng.SuiteRunner.runTest(SuiteRunner.java:421)
at org.testng.SuiteRunner.runSequentially(SuiteRunner.java:413)
at org.testng.SuiteRunner.privateRun(SuiteRunner.java:373)
at org.testng.SuiteRunner.run(SuiteRunner.java:312)
at org.testng.SuiteRunnerWorker.runSuite(SuiteRunnerWorker.java:52)
at org.testng.SuiteRunnerWorker.run(SuiteRunnerWorker.java:95)
at org.testng.TestNG.runSuitesSequentially(TestNG.java:1274)
at org.testng.TestNG.runSuitesLocally(TestNG.java:1208)
at org.testng.TestNG.runSuites(TestNG.java:1112)
at org.testng.TestNG.run(TestNG.java:1079)
at org.testng.remote.AbstractRemoteTestNG.run(AbstractRemoteTestNG.java:115)
at org.testng.remote.RemoteTestNG.initAndRun(RemoteTestNG.java:293)
at org.testng.remote.RemoteTestNG.main(RemoteTestNG.java:91)
]]>
    </failure>
  </testcase> <!-- loginSuccess -->
  <testcase classname="testcases.LoginTest" name="loginSuccessFromDataProvider" time="3.796">
    <failure message="FAIL Because Still in the Login page: expected [false] but found [true]" type="java.lang.AssertionError">
      <![CDATA[java.lang.AssertionError: FAIL Because Still in the Login page: expected [false] but found [true]
at org.testng.Assert.fail(Assert.java:111)
at org.testng.Assert.failNotEquals(Assert.java:1590)
at org.testng.Assert.assertFalse(Assert.java:79)
at keywords.WebUI.assertNotContains(WebUI.java:468)
at pages.LoginPage.verifyLoginSuccess(LoginPage.java:41)
at testcases.LoginTest.loginSuccessFromDataProvider(LoginTest.java:54)
at java.base/jdk.internal.reflect.DirectMethodHandleAccessor.invoke(DirectMethodHandleAccessor.java:103)
at java.base/java.lang.reflect.Method.invoke(Method.java:580)
at org.testng.internal.invokers.MethodInvocationHelper.invokeMethod(MethodInvocationHelper.java:141)
at org.testng.internal.invokers.TestInvoker.invokeMethod(TestInvoker.java:687)
at org.testng.internal.invokers.TestInvoker.invokeTestMethod(TestInvoker.java:230)
at org.testng.internal.invokers.MethodRunner.runInSequence(MethodRunner.java:63)
at org.testng.internal.invokers.TestInvoker$MethodInvocationAgent.invoke(TestInvoker.java:995)
at org.testng.internal.invokers.TestInvoker.invokeTestMethods(TestInvoker.java:203)
at org.testng.internal.invokers.TestMethodWorker.invokeTestMethods(TestMethodWorker.java:154)
at org.testng.internal.invokers.TestMethodWorker.run(TestMethodWorker.java:134)
at java.base/java.util.ArrayList.forEach(ArrayList.java:1596)
at org.testng.TestRunner.privateRun(TestRunner.java:741)
at org.testng.TestRunner.run(TestRunner.java:616)
at org.testng.SuiteRunner.runTest(SuiteRunner.java:421)
at org.testng.SuiteRunner.runSequentially(SuiteRunner.java:413)
at org.testng.SuiteRunner.privateRun(SuiteRunner.java:373)
at org.testng.SuiteRunner.run(SuiteRunner.java:312)
at org.testng.SuiteRunnerWorker.runSuite(SuiteRunnerWorker.java:52)
at org.testng.SuiteRunnerWorker.run(SuiteRunnerWorker.java:95)
at org.testng.TestNG.runSuitesSequentially(TestNG.java:1274)
at org.testng.TestNG.runSuitesLocally(TestNG.java:1208)
at org.testng.TestNG.runSuites(TestNG.java:1112)
at org.testng.TestNG.run(TestNG.java:1079)
at org.testng.remote.AbstractRemoteTestNG.run(AbstractRemoteTestNG.java:115)
at org.testng.remote.RemoteTestNG.initAndRun(RemoteTestNG.java:293)
at org.testng.remote.RemoteTestNG.main(RemoteTestNG.java:91)
]]>
    </failure>
  </testcase> <!-- loginSuccessFromDataProvider -->
  <testcase classname="testcases.LoginTest" name="loginSuccessFromDataProvider" time="3.438">
    <failure message="FAIL Because Still in the Login page: expected [false] but found [true]" type="java.lang.AssertionError">
      <![CDATA[java.lang.AssertionError: FAIL Because Still in the Login page: expected [false] but found [true]
at org.testng.Assert.fail(Assert.java:111)
at org.testng.Assert.failNotEquals(Assert.java:1590)
at org.testng.Assert.assertFalse(Assert.java:79)
at keywords.WebUI.assertNotContains(WebUI.java:468)
at pages.LoginPage.verifyLoginSuccess(LoginPage.java:41)
at testcases.LoginTest.loginSuccessFromDataProvider(LoginTest.java:54)
at java.base/jdk.internal.reflect.DirectMethodHandleAccessor.invoke(DirectMethodHandleAccessor.java:103)
at java.base/java.lang.reflect.Method.invoke(Method.java:580)
at org.testng.internal.invokers.MethodInvocationHelper.invokeMethod(MethodInvocationHelper.java:141)
at org.testng.internal.invokers.TestInvoker.invokeMethod(TestInvoker.java:687)
at org.testng.internal.invokers.TestInvoker.invokeTestMethod(TestInvoker.java:230)
at org.testng.internal.invokers.MethodRunner.runInSequence(MethodRunner.java:63)
at org.testng.internal.invokers.TestInvoker$MethodInvocationAgent.invoke(TestInvoker.java:995)
at org.testng.internal.invokers.TestInvoker.invokeTestMethods(TestInvoker.java:203)
at org.testng.internal.invokers.TestMethodWorker.invokeTestMethods(TestMethodWorker.java:154)
at org.testng.internal.invokers.TestMethodWorker.run(TestMethodWorker.java:134)
at java.base/java.util.ArrayList.forEach(ArrayList.java:1596)
at org.testng.TestRunner.privateRun(TestRunner.java:741)
at org.testng.TestRunner.run(TestRunner.java:616)
at org.testng.SuiteRunner.runTest(SuiteRunner.java:421)
at org.testng.SuiteRunner.runSequentially(SuiteRunner.java:413)
at org.testng.SuiteRunner.privateRun(SuiteRunner.java:373)
at org.testng.SuiteRunner.run(SuiteRunner.java:312)
at org.testng.SuiteRunnerWorker.runSuite(SuiteRunnerWorker.java:52)
at org.testng.SuiteRunnerWorker.run(SuiteRunnerWorker.java:95)
at org.testng.TestNG.runSuitesSequentially(TestNG.java:1274)
at org.testng.TestNG.runSuitesLocally(TestNG.java:1208)
at org.testng.TestNG.runSuites(TestNG.java:1112)
at org.testng.TestNG.run(TestNG.java:1079)
at org.testng.remote.AbstractRemoteTestNG.run(AbstractRemoteTestNG.java:115)
at org.testng.remote.RemoteTestNG.initAndRun(RemoteTestNG.java:293)
at org.testng.remote.RemoteTestNG.main(RemoteTestNG.java:91)
]]>
    </failure>
  </testcase> <!-- loginSuccessFromDataProvider -->
  <testcase classname="testcases.LoginTest" name="loginSuccessFromDataProvider" time="3.776">
    <failure message="FAIL Because Still in the Login page: expected [false] but found [true]" type="java.lang.AssertionError">
      <![CDATA[java.lang.AssertionError: FAIL Because Still in the Login page: expected [false] but found [true]
at org.testng.Assert.fail(Assert.java:111)
at org.testng.Assert.failNotEquals(Assert.java:1590)
at org.testng.Assert.assertFalse(Assert.java:79)
at keywords.WebUI.assertNotContains(WebUI.java:468)
at pages.LoginPage.verifyLoginSuccess(LoginPage.java:41)
at testcases.LoginTest.loginSuccessFromDataProvider(LoginTest.java:54)
at java.base/jdk.internal.reflect.DirectMethodHandleAccessor.invoke(DirectMethodHandleAccessor.java:103)
at java.base/java.lang.reflect.Method.invoke(Method.java:580)
at org.testng.internal.invokers.MethodInvocationHelper.invokeMethod(MethodInvocationHelper.java:141)
at org.testng.internal.invokers.TestInvoker.invokeMethod(TestInvoker.java:687)
at org.testng.internal.invokers.TestInvoker.invokeTestMethod(TestInvoker.java:230)
at org.testng.internal.invokers.MethodRunner.runInSequence(MethodRunner.java:63)
at org.testng.internal.invokers.TestInvoker$MethodInvocationAgent.invoke(TestInvoker.java:995)
at org.testng.internal.invokers.TestInvoker.invokeTestMethods(TestInvoker.java:203)
at org.testng.internal.invokers.TestMethodWorker.invokeTestMethods(TestMethodWorker.java:154)
at org.testng.internal.invokers.TestMethodWorker.run(TestMethodWorker.java:134)
at java.base/java.util.ArrayList.forEach(ArrayList.java:1596)
at org.testng.TestRunner.privateRun(TestRunner.java:741)
at org.testng.TestRunner.run(TestRunner.java:616)
at org.testng.SuiteRunner.runTest(SuiteRunner.java:421)
at org.testng.SuiteRunner.runSequentially(SuiteRunner.java:413)
at org.testng.SuiteRunner.privateRun(SuiteRunner.java:373)
at org.testng.SuiteRunner.run(SuiteRunner.java:312)
at org.testng.SuiteRunnerWorker.runSuite(SuiteRunnerWorker.java:52)
at org.testng.SuiteRunnerWorker.run(SuiteRunnerWorker.java:95)
at org.testng.TestNG.runSuitesSequentially(TestNG.java:1274)
at org.testng.TestNG.runSuitesLocally(TestNG.java:1208)
at org.testng.TestNG.runSuites(TestNG.java:1112)
at org.testng.TestNG.run(TestNG.java:1079)
at org.testng.remote.AbstractRemoteTestNG.run(AbstractRemoteTestNG.java:115)
at org.testng.remote.RemoteTestNG.initAndRun(RemoteTestNG.java:293)
at org.testng.remote.RemoteTestNG.main(RemoteTestNG.java:91)
]]>
    </failure>
  </testcase> <!-- loginSuccessFromDataProvider -->
  <testcase classname="testcases.LoginTest" name="loginSuccessFromDataProvider" time="3.754">
    <failure message="FAIL Because Still in the Login page: expected [false] but found [true]" type="java.lang.AssertionError">
      <![CDATA[java.lang.AssertionError: FAIL Because Still in the Login page: expected [false] but found [true]
at org.testng.Assert.fail(Assert.java:111)
at org.testng.Assert.failNotEquals(Assert.java:1590)
at org.testng.Assert.assertFalse(Assert.java:79)
at keywords.WebUI.assertNotContains(WebUI.java:468)
at pages.LoginPage.verifyLoginSuccess(LoginPage.java:41)
at testcases.LoginTest.loginSuccessFromDataProvider(LoginTest.java:54)
at java.base/jdk.internal.reflect.DirectMethodHandleAccessor.invoke(DirectMethodHandleAccessor.java:103)
at java.base/java.lang.reflect.Method.invoke(Method.java:580)
at org.testng.internal.invokers.MethodInvocationHelper.invokeMethod(MethodInvocationHelper.java:141)
at org.testng.internal.invokers.TestInvoker.invokeMethod(TestInvoker.java:687)
at org.testng.internal.invokers.TestInvoker.invokeTestMethod(TestInvoker.java:230)
at org.testng.internal.invokers.MethodRunner.runInSequence(MethodRunner.java:63)
at org.testng.internal.invokers.TestInvoker$MethodInvocationAgent.invoke(TestInvoker.java:995)
at org.testng.internal.invokers.TestInvoker.invokeTestMethods(TestInvoker.java:203)
at org.testng.internal.invokers.TestMethodWorker.invokeTestMethods(TestMethodWorker.java:154)
at org.testng.internal.invokers.TestMethodWorker.run(TestMethodWorker.java:134)
at java.base/java.util.ArrayList.forEach(ArrayList.java:1596)
at org.testng.TestRunner.privateRun(TestRunner.java:741)
at org.testng.TestRunner.run(TestRunner.java:616)
at org.testng.SuiteRunner.runTest(SuiteRunner.java:421)
at org.testng.SuiteRunner.runSequentially(SuiteRunner.java:413)
at org.testng.SuiteRunner.privateRun(SuiteRunner.java:373)
at org.testng.SuiteRunner.run(SuiteRunner.java:312)
at org.testng.SuiteRunnerWorker.runSuite(SuiteRunnerWorker.java:52)
at org.testng.SuiteRunnerWorker.run(SuiteRunnerWorker.java:95)
at org.testng.TestNG.runSuitesSequentially(TestNG.java:1274)
at org.testng.TestNG.runSuitesLocally(TestNG.java:1208)
at org.testng.TestNG.runSuites(TestNG.java:1112)
at org.testng.TestNG.run(TestNG.java:1079)
at org.testng.remote.AbstractRemoteTestNG.run(AbstractRemoteTestNG.java:115)
at org.testng.remote.RemoteTestNG.initAndRun(RemoteTestNG.java:293)
at org.testng.remote.RemoteTestNG.main(RemoteTestNG.java:91)
]]>
    </failure>
  </testcase> <!-- loginSuccessFromDataProvider -->
  <testcase classname="testcases.LoginTest" name="loginSuccessFromDataProvider" time="5.582"/>
  <testcase classname="testcases.LoginTest" name="loginSuccessFromDataProviderHashTable" time="4.661">
    <failure message="FAIL Because Still in the Login page: expected [false] but found [true]" type="java.lang.AssertionError">
      <![CDATA[java.lang.AssertionError: FAIL Because Still in the Login page: expected [false] but found [true]
at org.testng.Assert.fail(Assert.java:111)
at org.testng.Assert.failNotEquals(Assert.java:1590)
at org.testng.Assert.assertFalse(Assert.java:79)
at keywords.WebUI.assertNotContains(WebUI.java:468)
at pages.LoginPage.verifyLoginSuccess(LoginPage.java:41)
at testcases.LoginTest.loginSuccessFromDataProviderHashTable(LoginTest.java:67)
at java.base/jdk.internal.reflect.DirectMethodHandleAccessor.invoke(DirectMethodHandleAccessor.java:103)
at java.base/java.lang.reflect.Method.invoke(Method.java:580)
at org.testng.internal.invokers.MethodInvocationHelper.invokeMethod(MethodInvocationHelper.java:141)
at org.testng.internal.invokers.TestInvoker.invokeMethod(TestInvoker.java:687)
at org.testng.internal.invokers.TestInvoker.invokeTestMethod(TestInvoker.java:230)
at org.testng.internal.invokers.MethodRunner.runInSequence(MethodRunner.java:63)
at org.testng.internal.invokers.TestInvoker$MethodInvocationAgent.invoke(TestInvoker.java:995)
at org.testng.internal.invokers.TestInvoker.invokeTestMethods(TestInvoker.java:203)
at org.testng.internal.invokers.TestMethodWorker.invokeTestMethods(TestMethodWorker.java:154)
at org.testng.internal.invokers.TestMethodWorker.run(TestMethodWorker.java:134)
at java.base/java.util.ArrayList.forEach(ArrayList.java:1596)
at org.testng.TestRunner.privateRun(TestRunner.java:741)
at org.testng.TestRunner.run(TestRunner.java:616)
at org.testng.SuiteRunner.runTest(SuiteRunner.java:421)
at org.testng.SuiteRunner.runSequentially(SuiteRunner.java:413)
at org.testng.SuiteRunner.privateRun(SuiteRunner.java:373)
at org.testng.SuiteRunner.run(SuiteRunner.java:312)
at org.testng.SuiteRunnerWorker.runSuite(SuiteRunnerWorker.java:52)
at org.testng.SuiteRunnerWorker.run(SuiteRunnerWorker.java:95)
at org.testng.TestNG.runSuitesSequentially(TestNG.java:1274)
at org.testng.TestNG.runSuitesLocally(TestNG.java:1208)
at org.testng.TestNG.runSuites(TestNG.java:1112)
at org.testng.TestNG.run(TestNG.java:1079)
at org.testng.remote.AbstractRemoteTestNG.run(AbstractRemoteTestNG.java:115)
at org.testng.remote.RemoteTestNG.initAndRun(RemoteTestNG.java:293)
at org.testng.remote.RemoteTestNG.main(RemoteTestNG.java:91)
]]>
    </failure>
  </testcase> <!-- loginSuccessFromDataProviderHashTable -->
  <testcase classname="testcases.LoginTest" name="loginSuccessFromDataProviderHashTable" time="3.736">
    <failure message="FAIL Because Still in the Login page: expected [false] but found [true]" type="java.lang.AssertionError">
      <![CDATA[java.lang.AssertionError: FAIL Because Still in the Login page: expected [false] but found [true]
at org.testng.Assert.fail(Assert.java:111)
at org.testng.Assert.failNotEquals(Assert.java:1590)
at org.testng.Assert.assertFalse(Assert.java:79)
at keywords.WebUI.assertNotContains(WebUI.java:468)
at pages.LoginPage.verifyLoginSuccess(LoginPage.java:41)
at testcases.LoginTest.loginSuccessFromDataProviderHashTable(LoginTest.java:67)
at java.base/jdk.internal.reflect.DirectMethodHandleAccessor.invoke(DirectMethodHandleAccessor.java:103)
at java.base/java.lang.reflect.Method.invoke(Method.java:580)
at org.testng.internal.invokers.MethodInvocationHelper.invokeMethod(MethodInvocationHelper.java:141)
at org.testng.internal.invokers.TestInvoker.invokeMethod(TestInvoker.java:687)
at org.testng.internal.invokers.TestInvoker.invokeTestMethod(TestInvoker.java:230)
at org.testng.internal.invokers.MethodRunner.runInSequence(MethodRunner.java:63)
at org.testng.internal.invokers.TestInvoker$MethodInvocationAgent.invoke(TestInvoker.java:995)
at org.testng.internal.invokers.TestInvoker.invokeTestMethods(TestInvoker.java:203)
at org.testng.internal.invokers.TestMethodWorker.invokeTestMethods(TestMethodWorker.java:154)
at org.testng.internal.invokers.TestMethodWorker.run(TestMethodWorker.java:134)
at java.base/java.util.ArrayList.forEach(ArrayList.java:1596)
at org.testng.TestRunner.privateRun(TestRunner.java:741)
at org.testng.TestRunner.run(TestRunner.java:616)
at org.testng.SuiteRunner.runTest(SuiteRunner.java:421)
at org.testng.SuiteRunner.runSequentially(SuiteRunner.java:413)
at org.testng.SuiteRunner.privateRun(SuiteRunner.java:373)
at org.testng.SuiteRunner.run(SuiteRunner.java:312)
at org.testng.SuiteRunnerWorker.runSuite(SuiteRunnerWorker.java:52)
at org.testng.SuiteRunnerWorker.run(SuiteRunnerWorker.java:95)
at org.testng.TestNG.runSuitesSequentially(TestNG.java:1274)
at org.testng.TestNG.runSuitesLocally(TestNG.java:1208)
at org.testng.TestNG.runSuites(TestNG.java:1112)
at org.testng.TestNG.run(TestNG.java:1079)
at org.testng.remote.AbstractRemoteTestNG.run(AbstractRemoteTestNG.java:115)
at org.testng.remote.RemoteTestNG.initAndRun(RemoteTestNG.java:293)
at org.testng.remote.RemoteTestNG.main(RemoteTestNG.java:91)
]]>
    </failure>
  </testcase> <!-- loginSuccessFromDataProviderHashTable -->
  <testcase classname="testcases.LoginTest" name="loginSuccessFromDataProviderHashTable" time="4.090">
    <failure message="FAIL Because Still in the Login page: expected [false] but found [true]" type="java.lang.AssertionError">
      <![CDATA[java.lang.AssertionError: FAIL Because Still in the Login page: expected [false] but found [true]
at org.testng.Assert.fail(Assert.java:111)
at org.testng.Assert.failNotEquals(Assert.java:1590)
at org.testng.Assert.assertFalse(Assert.java:79)
at keywords.WebUI.assertNotContains(WebUI.java:468)
at pages.LoginPage.verifyLoginSuccess(LoginPage.java:41)
at testcases.LoginTest.loginSuccessFromDataProviderHashTable(LoginTest.java:67)
at java.base/jdk.internal.reflect.DirectMethodHandleAccessor.invoke(DirectMethodHandleAccessor.java:103)
at java.base/java.lang.reflect.Method.invoke(Method.java:580)
at org.testng.internal.invokers.MethodInvocationHelper.invokeMethod(MethodInvocationHelper.java:141)
at org.testng.internal.invokers.TestInvoker.invokeMethod(TestInvoker.java:687)
at org.testng.internal.invokers.TestInvoker.invokeTestMethod(TestInvoker.java:230)
at org.testng.internal.invokers.MethodRunner.runInSequence(MethodRunner.java:63)
at org.testng.internal.invokers.TestInvoker$MethodInvocationAgent.invoke(TestInvoker.java:995)
at org.testng.internal.invokers.TestInvoker.invokeTestMethods(TestInvoker.java:203)
at org.testng.internal.invokers.TestMethodWorker.invokeTestMethods(TestMethodWorker.java:154)
at org.testng.internal.invokers.TestMethodWorker.run(TestMethodWorker.java:134)
at java.base/java.util.ArrayList.forEach(ArrayList.java:1596)
at org.testng.TestRunner.privateRun(TestRunner.java:741)
at org.testng.TestRunner.run(TestRunner.java:616)
at org.testng.SuiteRunner.runTest(SuiteRunner.java:421)
at org.testng.SuiteRunner.runSequentially(SuiteRunner.java:413)
at org.testng.SuiteRunner.privateRun(SuiteRunner.java:373)
at org.testng.SuiteRunner.run(SuiteRunner.java:312)
at org.testng.SuiteRunnerWorker.runSuite(SuiteRunnerWorker.java:52)
at org.testng.SuiteRunnerWorker.run(SuiteRunnerWorker.java:95)
at org.testng.TestNG.runSuitesSequentially(TestNG.java:1274)
at org.testng.TestNG.runSuitesLocally(TestNG.java:1208)
at org.testng.TestNG.runSuites(TestNG.java:1112)
at org.testng.TestNG.run(TestNG.java:1079)
at org.testng.remote.AbstractRemoteTestNG.run(AbstractRemoteTestNG.java:115)
at org.testng.remote.RemoteTestNG.initAndRun(RemoteTestNG.java:293)
at org.testng.remote.RemoteTestNG.main(RemoteTestNG.java:91)
]]>
    </failure>
  </testcase> <!-- loginSuccessFromDataProviderHashTable -->
  <testcase classname="testcases.LoginTest" name="loginFailWithEmailInvalid" time="2.833"/>
  <testcase classname="testcases.LoginTest" name="loginFailWithPasswordInvalid" time="3.281"/>
  <testcase classname="testcases.LoginTest" name="loginFailWithEmailNull" time="2.500"/>
  <testcase classname="testcases.LoginTest" name="loginFailWithPasswordNull" time="2.580"/>
  <testcase classname="testcases.LoginTest" name="loginFailWithEmailNullAndPasswordNull" time="2.486"/>
</testsuite> <!-- testcases.LoginTest -->
